Workbook

Sheet README
A1: Калькулятор рейтинга скважин ГДИС
A4: Полная инструкция по работе с калькулятором
A6: № | B6: Раздел | C6: Практическое правило
A7: 1 | B7: Настройте критерии | C7: На листе «Настройки» выберите используемые критерии, задайте веса и параметры. Скрытые технические столбцы не редактируйте.
A8: 2 | B8: Введите данные | C8: На листе «Данные» одна строка должна соответствовать одной скважине. Не меняйте строку заголовков и структуру таблицы.
A9: 3 | B9: Соблюдайте формат | C9: Для логических признаков используйте только «Да» или «Нет» без звездочек и сносок. Числа вводите как числа, даты — как даты.
A10: 4 | B10: Проверьте μ | C10: На листе «Критерии» проверьте название критерия, вес, основание и рассчитанное μ. Формульные и скрытые ячейки не редактируйте.
A11: 5 | B11: Проверьте расчет | C11: На листе «Расчет» контролируйте активные и использованные критерии, пропуски, полноту данных, сумму весов, λ, место, статус и комментарий.
A12: 6 | B12: Посмотрите рейтинг | C12: На листе «Рейтинг» находится итоговый порядок и диаграмма. Количество отображаемых скважин определяется настройкой TOP-N.
B13: Как читать результаты
A14: μ | B14: Значение критерия | C14: μ показывает степень выполнения отдельного критерия. Обычно диапазон — от 0 до 1: чем выше μ, тем сильнее критерий повышает приоритет.
A15: Вес | B15: Вклад критерия | C15: Вес определяет относительный вклад критерия в итоговый расчет. После изменения весов проверьте контроль суммы весов на листе «Настройки».
A16: λ | B16: Итоговый коэффициент | C16: λ объединяет значения μ с учетом весов. Чем выше λ, тем выше итоговый приоритет скважины.
A17: Место | B17: Позиция в рейтинге | C17: Место 1 соответствует наивысшему приоритету. При одинаковом λ порядок определяется действующей расчетной формулой книги.
A18: Статус | B18: Кандидат или резерв | C18: Статус формируется по настройкам режима отбора, порогу λ, количеству оснований и TOP-N. Для объяснения результата смотрите комментарий.
B19: Важные правила ввода
A20: 1 | B20: Номер скважины | C20: Номер скважины является текстовым идентификатором. Значения 001, 005, 010 и 081 должны вводиться и храниться с ведущими нулями.
A21: 2 | B21: Да / Нет | C21: Используйте только чистые значения «Да» и «Нет». Не вводите «Да*», «Да**», «Нет*» и другие пояснительные символы.
A22: 3 | B22: Числовые значения | C22: Не добавляйте звездочки к числам. Например, вводите 0,4 или 2,7 как числовые значения; пояснения размещайте в предусмотренном поле комментария.
A23: 4 | B23: Пропуски | C23: Если исходного значения нет, оставьте ячейку пустой. Не заменяйте пропуск нулем, текстом «нет данных» или дефисом без отдельного правила.
A24: 5 | B24: Формулы и техника | C24: Не удаляйте и не заменяйте формулы значениями. Не показывайте и не редактируйте скрытые технические строки и столбцы без необходимости.
A25: 6 | B25: Пересчет | C25: Книга настроена на автоматический полный пересчет при открытии Excel. После открытия дождитесь завершения расчета перед анализом рейтинга.
B26: Назначение листов
A27: 1 | B27: Настройки | C27: Включение критериев, веса, типы правил, поля данных, пороги, параметры сигмоиды, политика пропусков, режим отбора и TOP-N.
A28: 2 | B28: Данные | C28: Пользовательский ввод исходных сведений по скважинам. Одна скважина — одна строка; номер скважины хранится как текст.
A29: 3 | B29: Критерии | C29: Расчет μ по каждой скважине и каждому активному критерию. Пользовательская часть предназначена для просмотра результата.
A30: 4 | B30: Расчет | C30: Сводный расчет полноты данных, суммы весов, λ, места, статуса, комментария и основных сработавших критериев.
A31: 5 | B31: Рейтинг | C31: Итоговый ранжированный список скважин и диаграмма TOP-N.
B32: Контроль перед использованием
A33: 1 | B33: Проверьте данные | C33: Убедитесь, что номера скважин сохранены как текст, значения «Да/Нет» очищены, а числовые поля действительно содержат числа.
A34: 2 | B34: Проверьте настройки | C34: Убедитесь, что нужные критерии включены, веса и параметры заданы корректно, а контроль весов не показывает предупреждение.
A35: 3 | B35: Проверьте расчет | C35: Убедитесь, что в пользовательских результатах нет сообщений об ошибке или некорректных настройках и что полнота данных достаточна.
A36: 4 | B36: Используйте результат | C36: Сначала анализируйте λ и место, затем статус, комментарий и основные критерии. При изменении данных или настроек дождитесь нового пересчета.

Sheet Настройки
A1: Настройки калькулятора | B1: Настройки калькулятора | C1: Настройки калькулятора | D1: Настройки калькулятора | E1: Настройки калькулятора | F1: Настройки калькулятора | G1: Настройки калькулятора | H1: Настройки калькулятора | I1: Настройки калькулятора | J1: Настройки калькулятора | K1: Настройки калькулятора | L1: Настройки калькулятора | M1: Настройки калькулятора | N1: Настройки калькулятора | O1: Настройки калькулятора | P1: Настройки калькулятора | Q1: Настройки калькулятора | R1: Настройки калькулятора | S1: Настройки калькулятора | T1: Настройки калькулятора | U1: Настройки калькулятора
A2: Настройки калькулятора | B2: Настройки калькулятора | C2: Настройки калькулятора | D2: Настройки калькулятора | E2: Настройки калькулятора | F2: Настройки калькулятора | G2: Настройки калькулятора | H2: Настройки калькулятора | I2: Настройки калькулятора | J2: Настройки калькулятора | K2: Настройки калькулятора | L2: Настройки калькулятора | M2: Настройки калькулятора | N2: Настройки калькулятора | O2: Настройки калькулятора | P2: Настройки калькулятора | Q2: Настройки калькулятора | R2: Настройки калькулятора | S2: Настройки калькулятора | T2: Настройки калькулятора | U2: Настройки калькулятора
A3: ОБЩИЕ НАСТРОЙКИ | B3: ОБЩИЕ НАСТРОЙКИ | C3: ОБЩИЕ НАСТРОЙКИ | D3: ОБЩИЕ НАСТРОЙКИ
A5: μ Да | B5: 1 | C5: Условие выполнено
A6: μ Нет | B6: 0.1 | C6: Условие не выполнено
A7: Расчет λ | B7: Взвешенное геометрическое | C7: Итог по весам и μ
A8: Минимум оснований | B8: 1 | C8: Для статуса «Кандидат»
A9: ТОП-N | B9: 5 | C9: Количество строк на диаграмме
A10: Порог λ | B10: 0.15 | C10: Для правила «Порог λ»
A11: Правило отбора | B11: ТОП-N | C11: ТОП-N / Порог λ / только ранжирование
A12: Если нет данных | B12: Блокировать | C12: Общее действие по умолчанию
A13: Допуск суммы весов | B13: 0.0001 | C13: Служебная настройка
A14: Минимальное μ | B14: 1e-09 | C14: Защита расчета
A15: Нейтральное μ | B15: 1 | C15: Служебная настройка
A16: Порог основания (μ) | B16: 0.5 | C16: Условие считается выполненным
A17: Сумма весов | B17: =SUMIF($A$21:$A$50,"Да",$D$21:$D$50) -> 1
A18: Проверка весов | B18: =IF(ABS(B17-1)<=B13,"OK","Проверить веса") -> OK
A19: КРИТЕРИИ — желтые ячейки можно изменять | B19: КРИТЕРИИ — желтые ячейки можно изменять | C19: КРИТЕРИИ — желтые ячейки можно изменять | D19: КРИТЕРИИ — желтые ячейки можно изменять | E19: КРИТЕРИИ — желтые ячейки можно изменять | F19: КРИТЕРИИ — желтые ячейки можно изменять | G19: КРИТЕРИИ — желтые ячейки можно изменять | H19: КРИТЕРИИ — желтые ячейки можно изменять | I19: КРИТЕРИИ — желтые ячейки можно изменять | J19: КРИТЕРИИ — желтые ячейки можно изменять | K19: КРИТЕРИИ — желтые ячейки можно изменять | L19: КРИТЕРИИ — желтые ячейки можно изменять | M19: КРИТЕРИИ — желтые ячейки можно изменять | N19: КРИТЕРИИ — желтые ячейки можно изменять | O19: КРИТЕРИИ — желтые ячейки можно изменять | P19: КРИТЕРИИ — желтые ячейки можно изменять | Q19: КРИТЕРИИ — желтые ячейки можно изменять | R19: КРИТЕРИИ — желтые ячейки можно изменять | S19: КРИТЕРИИ — желтые ячейки можно изменять | T19: КРИТЕРИИ — желтые ячейки можно изменять | U19: КРИТЕРИИ — желтые ячейки можно изменять
A20: Использовать | B20: Критерий | C20: Тип расчета | D20: Вес | E20: Поле 1 | F20: Поле 2 | G20: Порог / середина | H20: Крутизна | I20: μ Да | J20: μ Нет | K20: Основание для кандидата | L20: Если нет данных | M20: Комментарий | N20: Код | O20: Порядок | P20: Код типа | Q20: Доп. параметр | R20: μ min | S20: μ max | T20: Код пропуска | U20: Категория
A21: Да | B21: Запланировано или проведено ГТМ | C21: Да / Нет | D21: 0.2 | E21: ГТМ | I21: 1 | J21: 0.1 | K21: Да | L21: Блокировать | M21: Качественный критерий | N21: C01_GTM | O21: 1 | P21: =IF(C21="Да / Нет","YES_NO",IF(C21="Не меньше порога","THRESHOLD_GE",IF(C21="Больше порога","THRESHOLD_GT",IF(C21="Не больше порога","THRESHOLD_LE",IF(C21="Меньше порога","THRESHOLD_LT",IF(C21="Рост показателя","CHANGE_PCT_GE",IF(C21="Изменение показателя","CHANGE_ABS_GE",IF(C21="Количество меньше","COUNT_LT",IF(C21="Количество не больше","COUNT_LE",IF(C21="Сигмоида","SIGMOID_INC",IF(C21="Сигмоида (убывание)","SIGMOID_DEC",IF(C21="ТОП %","TOP_PERCENT",IF(C21="Ручное μ","MANUAL_MU",IF(C21="Количество + флаг","COUNT_FLAG_RULE",IF(C21="Все условия «Да»","AND_YES",IF(C21="Любое условие «Да»","OR_YES","")))))))))))))))) -> YES_NO | R21: 1e-09 | S21: 1 | T21: =IF(L21="Минимум","LOW_MU",IF(L21="Не учитывать","IGNORE","BLOCK")) -> BLOCK | U21: Качественный
A22: Да | B22: Недостаточно ГДИС для создания модели пласт-скважина | C22: Да / Нет | D22: 0.14 | E22: Недостаточно ГДИС | I22: 1 | J22: 0.1 | K22: Да | L22: Блокировать | M22: Недостаточно исследований | N22: C02_GDIS | O22: 2 | P22: =IF(C22="Да / Нет","YES_NO",IF(C22="Не меньше порога","THRESHOLD_GE",IF(C22="Больше порога","THRESHOLD_GT",IF(C22="Не больше порога","THRESHOLD_LE",IF(C22="Меньше порога","THRESHOLD_LT",IF(C22="Рост показателя","CHANGE_PCT_GE",IF(C22="Изменение показателя","CHANGE_ABS_GE",IF(C22="Количество меньше","COUNT_LT",IF(C22="Количество не больше","COUNT_LE",IF(C22="Сигмоида","SIGMOID_INC",IF(C22="Сигмоида (убывание)","SIGMOID_DEC",IF(C22="ТОП %","TOP_PERCENT",IF(C22="Ручное μ","MANUAL_MU",IF(C22="Количество + флаг","COUNT_FLAG_RULE",IF(C22="Все условия «Да»","AND_YES",IF(C22="Любое условие «Да»","OR_YES","")))))))))))))))) -> YES_NO | R22: 1e-09 | S22: 1 | T22: =IF(L22="Минимум","LOW_MU",IF(L22="Не учитывать","IGNORE","BLOCK")) -> BLOCK | U22: Качественный
A23: Да | B23: Наблюдается снижение продуктивности | C23: Да / Нет | D23: 0.12 | E23: Снижение продуктивности | I23: 1 | J23: 0.1 | K23: Да | L23: Блокировать | M23: Снижение продуктивности | N23: C03_PROD | O23: 3 | P23: =IF(C23="Да / Нет","YES_NO",IF(C23="Не меньше порога","THRESHOLD_GE",IF(C23="Больше порога","THRESHOLD_GT",IF(C23="Не больше порога","THRESHOLD_LE",IF(C23="Меньше порога","THRESHOLD_LT",IF(C23="Рост показателя","CHANGE_PCT_GE",IF(C23="Изменение показателя","CHANGE_ABS_GE",IF(C23="Количество меньше","COUNT_LT",IF(C23="Количество не больше","COUNT_LE",IF(C23="Сигмоида","SIGMOID_INC",IF(C23="Сигмоида (убывание)","SIGMOID_DEC",IF(C23="ТОП %","TOP_PERCENT",IF(C23="Ручное μ","MANUAL_MU",IF(C23="Количество + флаг","COUNT_FLAG_RULE",IF(C23="Все условия «Да»","AND_YES",IF(C23="Любое условие «Да»","OR_YES","")))))))))))))))) -> YES_NO | R23: 1e-09 | S23: 1 | T23: =IF(L23="Минимум","LOW_MU",IF(L23="Не учитывать","IGNORE","BLOCK")) -> BLOCK | U23: Качественный
A24: Да | B24: Рост хлора | C24: Да / Нет | D24: 0.12 | E24: Рост хлора | I24: 1 | J24: 0.1 | K24: Да | L24: Блокировать | M24: Рост хлора | N24: C04_CL | O24: 4 | P24: =IF(C24="Да / Нет","YES_NO",IF(C24="Не меньше порога","THRESHOLD_GE",IF(C24="Больше порога","THRESHOLD_GT",IF(C24="Не больше порога","THRESHOLD_LE",IF(C24="Меньше порога","THRESHOLD_LT",IF(C24="Рост показателя","CHANGE_PCT_GE",IF(C24="Изменение показателя","CHANGE_ABS_GE",IF(C24="Количество меньше","COUNT_LT",IF(C24="Количество не больше","COUNT_LE",IF(C24="Сигмоида","SIGMOID_INC",IF(C24="Сигмоида (убывание)","SIGMOID_DEC",IF(C24="ТОП %","TOP_PERCENT",IF(C24="Ручное μ","MANUAL_MU",IF(C24="Количество + флаг","COUNT_FLAG_RULE",IF(C24="Все условия «Да»","AND_YES",IF(C24="Любое условие «Да»","OR_YES","")))))))))))))))) -> YES_NO | R24: 1e-09 | S24: 1 | T24: =IF(L24="Минимум","LOW_MU",IF(L24="Не учитывать","IGNORE","BLOCK")) -> BLOCK | U24: Качественный
A25: Да | B25: Проблемы с адаптацией в ГДМ | C25: Да / Нет | D25: 0.12 | E25: Проблемы ГДМ | I25: 1 | J25: 0.1 | K25: Да | L25: Блокировать | M25: Проблемы адаптации модели | N25: C05_GDM | O25: 5 | P25: =IF(C25="Да / Нет","YES_NO",IF(C25="Не меньше порога","THRESHOLD_GE",IF(C25="Больше порога","THRESHOLD_GT",IF(C25="Не больше порога","THRESHOLD_LE",IF(C25="Меньше порога","THRESHOLD_LT",IF(C25="Рост показателя","CHANGE_PCT_GE",IF(C25="Изменение показателя","CHANGE_ABS_GE",IF(C25="Количество меньше","COUNT_LT",IF(C25="Количество не больше","COUNT_LE",IF(C25="Сигмоида","SIGMOID_INC",IF(C25="Сигмоида (убывание)","SIGMOID_DEC",IF(C25="ТОП %","TOP_PERCENT",IF(C25="Ручное μ","MANUAL_MU",IF(C25="Количество + флаг","COUNT_FLAG_RULE",IF(C25="Все условия «Да»","AND_YES",IF(C25="Любое условие «Да»","OR_YES","")))))))))))))))) -> YES_NO | R25: 1e-09 | S25: 1 | T25: =IF(L25="Минимум","LOW_MU",IF(L25="Не учитывать","IGNORE","BLOCK")) -> BLOCK | U25: Качественный
A26: Да | B26: Невыход на радиальный режим / низкая достоверность ЛНД | C26: Да / Нет | D26: 0.1 | E26: ЛНД | I26: 1 | J26: 0.1 | K26: Да | L26: Блокировать | M26: Низкая достоверность | N26: C06_LND | O26: 6 | P26: =IF(C26="Да / Нет","YES_NO",IF(C26="Не меньше порога","THRESHOLD_GE",IF(C26="Больше порога","THRESHOLD_GT",IF(C26="Не больше порога","THRESHOLD_LE",IF(C26="Меньше порога","THRESHOLD_LT",IF(C26="Рост показателя","CHANGE_PCT_GE",IF(C26="Изменение показателя","CHANGE_ABS_GE",IF(C26="Количество меньше","COUNT_LT",IF(C26="Количество не больше","COUNT_LE",IF(C26="Сигмоида","SIGMOID_INC",IF(C26="Сигмоида (убывание)","SIGMOID_DEC",IF(C26="ТОП %","TOP_PERCENT",IF(C26="Ручное μ","MANUAL_MU",IF(C26="Количество + флаг","COUNT_FLAG_RULE",IF(C26="Все условия «Да»","AND_YES",IF(C26="Любое условие «Да»","OR_YES","")))))))))))))))) -> YES_NO | R26: 1e-09 | S26: 1 | T26: =IF(L26="Минимум","LOW_MU",IF(L26="Не учитывать","IGNORE","BLOCK")) -> BLOCK | U26: Качественный
A27: Да | B27: Продолжительность пребывания без ГДИ | C27: Сигмоида | D27: 0.1 | E27: Продолжительность без ГДИ | G27: 1.0863014 | H27: 8.25 | I27: 1 | J27: 0.1 | K27: Нет | L27: Блокировать | M27: Середина и крутизна перехода | N27: C07_NO_GDI | O27: 7 | P27: =IF(C27="Да / Нет","YES_NO",IF(C27="Не меньше порога","THRESHOLD_GE",IF(C27="Больше порога","THRESHOLD_GT",IF(C27="Не больше порога","THRESHOLD_LE",IF(C27="Меньше порога","THRESHOLD_LT",IF(C27="Рост показателя","CHANGE_PCT_GE",IF(C27="Изменение показателя","CHANGE_ABS_GE",IF(C27="Количество меньше","COUNT_LT",IF(C27="Количество не больше","COUNT_LE",IF(C27="Сигмоида","SIGMOID_INC",IF(C27="Сигмоида (убывание)","SIGMOID_DEC",IF(C27="ТОП %","TOP_PERCENT",IF(C27="Ручное μ","MANUAL_MU",IF(C27="Количество + флаг","COUNT_FLAG_RULE",IF(C27="Все условия «Да»","AND_YES",IF(C27="Любое условие «Да»","OR_YES","")))))))))))))))) -> SIGMOID_INC | R27: 0 | S27: 1 | T27: =IF(L27="Минимум","LOW_MU",IF(L27="Не учитывать","IGNORE","BLOCK")) -> BLOCK | U27: Количественный
A28: Да | B28: Не проведен АДД за скользящий год | C28: Да / Нет | D28: 0.05 | E28: Не проведен АДД | I28: 1 | J28: 0.1 | K28: Да | L28: Блокировать | M28: Нет исследования за год | N28: C08_NO_ADD | O28: 8 | P28: =IF(C28="Да / Нет","YES_NO",IF(C28="Не меньше порога","THRESHOLD_GE",IF(C28="Больше порога","THRESHOLD_GT",IF(C28="Не больше порога","THRESHOLD_LE",IF(C28="Меньше порога","THRESHOLD_LT",IF(C28="Рост показателя","CHANGE_PCT_GE",IF(C28="Изменение показателя","CHANGE_ABS_GE",IF(C28="Количество меньше","COUNT_LT",IF(C28="Количество не больше","COUNT_LE",IF(C28="Сигмоида","SIGMOID_INC",IF(C28="Сигмоида (убывание)","SIGMOID_DEC",IF(C28="ТОП %","TOP_PERCENT",IF(C28="Ручное μ","MANUAL_MU",IF(C28="Количество + флаг","COUNT_FLAG_RULE",IF(C28="Все условия «Да»","AND_YES",IF(C28="Любое условие «Да»","OR_YES","")))))))))))))))) -> YES_NO | R28: 1e-09 | S28: 1 | T28: =IF(L28="Минимум","LOW_MU",IF(L28="Не учитывать","IGNORE","BLOCK")) -> BLOCK | U28: Качественный
A29: Да | B29: Удельное количество ГДИ от накопленного периода работы | C29: Сигмоида | D29: 0.05 | E29: Удельное количество ГДИ | G29: 0.8462519 | H29: 18.76 | I29: 1 | J29: 0.1 | K29: Нет | L29: Блокировать | M29: Середина и крутизна перехода | N29: C09_SPEC_GDI | O29: 9 | P29: =IF(C29="Да / Нет","YES_NO",IF(C29="Не меньше порога","THRESHOLD_GE",IF(C29="Больше порога","THRESHOLD_GT",IF(C29="Не больше порога","THRESHOLD_LE",IF(C29="Меньше порога","THRESHOLD_LT",IF(C29="Рост показателя","CHANGE_PCT_GE",IF(C29="Изменение показателя","CHANGE_ABS_GE",IF(C29="Количество меньше","COUNT_LT",IF(C29="Количество не больше","COUNT_LE",IF(C29="Сигмоида","SIGMOID_INC",IF(C29="Сигмоида (убывание)","SIGMOID_DEC",IF(C29="ТОП %","TOP_PERCENT",IF(C29="Ручное μ","MANUAL_MU",IF(C29="Количество + флаг","COUNT_FLAG_RULE",IF(C29="Все условия «Да»","AND_YES",IF(C29="Любое условие «Да»","OR_YES","")))))))))))))))) -> SIGMOID_INC | R29: 0 | S29: 1 | T29: =IF(L29="Минимум","LOW_MU",IF(L29="Не учитывать","IGNORE","BLOCK")) -> BLOCK | U29: Количественный
A30: Нет | B30: Рост ВГФ | C30: Рост показателя | D30: 0.08 | E30: ВГФ текущий | F30: ВГФ предыдущий | I30: 1 | J30: 0.1 | K30: Да | L30: Блокировать | M30: Укажите порог роста | N30: C10_VGF_GROWTH | O30: 10 | P30: =IF(C30="Да / Нет","YES_NO",IF(C30="Не меньше порога","THRESHOLD_GE",IF(C30="Больше порога","THRESHOLD_GT",IF(C30="Не больше порога","THRESHOLD_LE",IF(C30="Меньше порога","THRESHOLD_LT",IF(C30="Рост показателя","CHANGE_PCT_GE",IF(C30="Изменение показателя","CHANGE_ABS_GE",IF(C30="Количество меньше","COUNT_LT",IF(C30="Количество не больше","COUNT_LE",IF(C30="Сигмоида","SIGMOID_INC",IF(C30="Сигмоида (убывание)","SIGMOID_DEC",IF(C30="ТОП %","TOP_PERCENT",IF(C30="Ручное μ","MANUAL_MU",IF(C30="Количество + флаг","COUNT_FLAG_RULE",IF(C30="Все условия «Да»","AND_YES",IF(C30="Любое условие «Да»","OR_YES","")))))))))))))))) -> CHANGE_PCT_GE | R30: 1e-09 | S30: 1 | T30: =IF(L30="Минимум","LOW_MU",IF(L30="Не учитывать","IGNORE","BLOCK")) -> BLOCK | U30: Качественный
A31: Нет | B31: Превышение предельного ВГФ | C31: Больше порога | D31: 0.08 | E31: ВГФ текущий | G31: 200 | I31: 1 | J31: 0.1 | K31: Да | L31: Блокировать | M31: Порог значения показателя | N31: C11_VGF_LIMIT | O31: 11 | P31: =IF(C31="Да / Нет","YES_NO",IF(C31="Не меньше порога","THRESHOLD_GE",IF(C31="Больше порога","THRESHOLD_GT",IF(C31="Не больше порога","THRESHOLD_LE",IF(C31="Меньше порога","THRESHOLD_LT",IF(C31="Рост показателя","CHANGE_PCT_GE",IF(C31="Изменение показателя","CHANGE_ABS_GE",IF(C31="Количество меньше","COUNT_LT",IF(C31="Количество не больше","COUNT_LE",IF(C31="Сигмоида","SIGMOID_INC",IF(C31="Сигмоида (убывание)","SIGMOID_DEC",IF(C31="ТОП %","TOP_PERCENT",IF(C31="Ручное μ","MANUAL_MU",IF(C31="Количество + флаг","COUNT_FLAG_RULE",IF(C31="Все условия «Да»","AND_YES",IF(C31="Любое условие «Да»","OR_YES","")))))))))))))))) -> THRESHOLD_GT | R31: 1e-09 | S31: 1 | T31: =IF(L31="Минимум","LOW_MU",IF(L31="Не учитывать","IGNORE","BLOCK")) -> BLOCK | U31: Качественный
A32: Нет | B32: Продолжительность пребывания без ИД | C32: Сигмоида | D32: 0.14 | E32: Продолжительность без ИД | I32: 1 | J32: 0.1 | K32: Нет | L32: Блокировать | M32: Заполните середину и крутизну | N32: C12_NO_ID | O32: 12 | P32: =IF(C32="Да / Нет","YES_NO",IF(C32="Не меньше порога","THRESHOLD_GE",IF(C32="Больше порога","THRESHOLD_GT",IF(C32="Не больше порога","THRESHOLD_LE",IF(C32="Меньше порога","THRESHOLD_LT",IF(C32="Рост показателя","CHANGE_PCT_GE",IF(C32="Изменение показателя","CHANGE_ABS_GE",IF(C32="Количество меньше","COUNT_LT",IF(C32="Количество не больше","COUNT_LE",IF(C32="Сигмоида","SIGMOID_INC",IF(C32="Сигмоида (убывание)","SIGMOID_DEC",IF(C32="ТОП %","TOP_PERCENT",IF(C32="Ручное μ","MANUAL_MU",IF(C32="Количество + флаг","COUNT_FLAG_RULE",IF(C32="Все условия «Да»","AND_YES",IF(C32="Любое условие «Да»","OR_YES","")))))))))))))))) -> SIGMOID_INC | R32: 1e-09 | S32: 1 | T32: =IF(L32="Минимум","LOW_MU",IF(L32="Не учитывать","IGNORE","BLOCK")) -> BLOCK | U32: Количественный
A33: Нет | B33: Продолжительность пребывания без КВД | C33: Сигмоида | D33: 0.1 | E33: Продолжительность без КВД | I33: 1 | J33: 0.1 | K33: Нет | L33: Блокировать | M33: Заполните середину и крутизну | N33: C13_NO_KVD | O33: 13 | P33: =IF(C33="Да / Нет","YES_NO",IF(C33="Не меньше порога","THRESHOLD_GE",IF(C33="Больше порога","THRESHOLD_GT",IF(C33="Не больше порога","THRESHOLD_LE",IF(C33="Меньше порога","THRESHOLD_LT",IF(C33="Рост показателя","CHANGE_PCT_GE",IF(C33="Изменение показателя","CHANGE_ABS_GE",IF(C33="Количество меньше","COUNT_LT",IF(C33="Количество не больше","COUNT_LE",IF(C33="Сигмоида","SIGMOID_INC",IF(C33="Сигмоида (убывание)","SIGMOID_DEC",IF(C33="ТОП %","TOP_PERCENT",IF(C33="Ручное μ","MANUAL_MU",IF(C33="Количество + флаг","COUNT_FLAG_RULE",IF(C33="Все условия «Да»","AND_YES",IF(C33="Любое условие «Да»","OR_YES","")))))))))))))))) -> SIGMOID_INC | R33: 1e-09 | S33: 1 | T33: =IF(L33="Минимум","LOW_MU",IF(L33="Не учитывать","IGNORE","BLOCK")) -> BLOCK | U33: Количественный
A34: Нет | B34: Возможность проведения исследований | C34: Да / Нет | D34: 0.05 | E34: Техническая возможность | I34: 1 | J34: 0.1 | K34: Да | L34: Блокировать | M34: Техническая возможность | N34: C14_TECH | O34: 14 | P34: =IF(C34="Да / Нет","YES_NO",IF(C34="Не меньше порога","THRESHOLD_GE",IF(C34="Больше порога","THRESHOLD_GT",IF(C34="Не больше порога","THRESHOLD_LE",IF(C34="Меньше порога","THRESHOLD_LT",IF(C34="Рост показателя","CHANGE_PCT_GE",IF(C34="Изменение показателя","CHANGE_ABS_GE",IF(C34="Количество меньше","COUNT_LT",IF(C34="Количество не больше","COUNT_LE",IF(C34="Сигмоида","SIGMOID_INC",IF(C34="Сигмоида (убывание)","SIGMOID_DEC",IF(C34="ТОП %","TOP_PERCENT",IF(C34="Ручное μ","MANUAL_MU",IF(C34="Количество + флаг","COUNT_FLAG_RULE",IF(C34="Все условия «Да»","AND_YES",IF(C34="Любое условие «Да»","OR_YES","")))))))))))))))) -> YES_NO | R34: 1e-09 | S34: 1 | T34: =IF(L34="Минимум","LOW_MU",IF(L34="Не учитывать","IGNORE","BLOCK")) -> BLOCK | U34: Качественный
A35: Нет | B35: Высокодебитные скважины | C35: ТОП % | D35: 0.1 | E35: Дебит | G35: 0.1 | I35: 1 | J35: 0.1 | K35: Нет | L35: Блокировать | M35: Доля фонда с наибольшим дебитом | N35: C15_TOP_DEBIT | O35: 15 | P35: =IF(C35="Да / Нет","YES_NO",IF(C35="Не меньше порога","THRESHOLD_GE",IF(C35="Больше порога","THRESHOLD_GT",IF(C35="Не больше порога","THRESHOLD_LE",IF(C35="Меньше порога","THRESHOLD_LT",IF(C35="Рост показателя","CHANGE_PCT_GE",IF(C35="Изменение показателя","CHANGE_ABS_GE",IF(C35="Количество меньше","COUNT_LT",IF(C35="Количество не больше","COUNT_LE",IF(C35="Сигмоида","SIGMOID_INC",IF(C35="Сигмоида (убывание)","SIGMOID_DEC",IF(C35="ТОП %","TOP_PERCENT",IF(C35="Ручное μ","MANUAL_MU",IF(C35="Количество + флаг","COUNT_FLAG_RULE",IF(C35="Все условия «Да»","AND_YES",IF(C35="Любое условие «Да»","OR_YES","")))))))))))))))) -> TOP_PERCENT | R35: 1e-09 | S35: 1 | T35: =IF(L35="Минимум","LOW_MU",IF(L35="Не учитывать","IGNORE","BLOCK")) -> BLOCK | U35: Количественный
A36: Нет | B36: Достаточность ГДИС с учетом стационарного оснащения | C36: Количество + флаг | D36: 0 | E36: Количество ГДИ | F36: Глубинные датчики | G36: 0 | H36: 2 | I36: 1 | J36: 0.1 | K36: Да | L36: Блокировать | M36: Количество исследований и оснащение | N36: C16_GDIS_RULE | O36: 16 | P36: =IF(C36="Да / Нет","YES_NO",IF(C36="Не меньше порога","THRESHOLD_GE",IF(C36="Больше порога","THRESHOLD_GT",IF(C36="Не больше порога","THRESHOLD_LE",IF(C36="Меньше порога","THRESHOLD_LT",IF(C36="Рост показателя","CHANGE_PCT_GE",IF(C36="Изменение показателя","CHANGE_ABS_GE",IF(C36="Количество меньше","COUNT_LT",IF(C36="Количество не больше","COUNT_LE",IF(C36="Сигмоида","SIGMOID_INC",IF(C36="Сигмоида (убывание)","SIGMOID_DEC",IF(C36="ТОП %","TOP_PERCENT",IF(C36="Ручное μ","MANUAL_MU",IF(C36="Количество + флаг","COUNT_FLAG_RULE",IF(C36="Все условия «Да»","AND_YES",IF(C36="Любое условие «Да»","OR_YES","")))))))))))))))) -> COUNT_FLAG_RULE | Q36: 0.5 | R36: 1e-09 | S36: 1 | T36: =IF(L36="Минимум","LOW_MU",IF(L36="Не учитывать","IGNORE","BLOCK")) -> BLOCK | U36: Качественный
A37: Нет | D37: 0 | I37: 1 | J37: 0.1 | K37: Нет | L37: Блокировать | M37: Свободный критерий | O37: 17 | P37: =IF(C37="Да / Нет","YES_NO",IF(C37="Не меньше порога","THRESHOLD_GE",IF(C37="Больше порога","THRESHOLD_GT",IF(C37="Не больше порога","THRESHOLD_LE",IF(C37="Меньше порога","THRESHOLD_LT",IF(C37="Рост показателя","CHANGE_PCT_GE",IF(C37="Изменение показателя","CHANGE_ABS_GE",IF(C37="Количество меньше","COUNT_LT",IF(C37="Количество не больше","COUNT_LE",IF(C37="Сигмоида","SIGMOID_INC",IF(C37="Сигмоида (убывание)","SIGMOID_DEC",IF(C37="ТОП %","TOP_PERCENT",IF(C37="Ручное μ","MANUAL_MU",IF(C37="Количество + флаг","COUNT_FLAG_RULE",IF(C37="Все условия «Да»","AND_YES",IF(C37="Любое условие «Да»","OR_YES","")))))))))))))))) | R37: 1e-09 | S37: 1 | T37: =IF(L37="Минимум","LOW_MU",IF(L37="Не учитывать","IGNORE","BLOCK")) -> BLOCK
A38: Нет | D38: 0 | I38: 1 | J38: 0.1 | K38: Нет | L38: Блокировать | M38: Свободный критерий | O38: 18 | P38: =IF(C38="Да / Нет","YES_NO",IF(C38="Не меньше порога","THRESHOLD_GE",IF(C38="Больше порога","THRESHOLD_GT",IF(C38="Не больше порога","THRESHOLD_LE",IF(C38="Меньше порога","THRESHOLD_LT",IF(C38="Рост показателя","CHANGE_PCT_GE",IF(C38="Изменение показателя","CHANGE_ABS_GE",IF(C38="Количество меньше","COUNT_LT",IF(C38="Количество не больше","COUNT_LE",IF(C38="Сигмоида","SIGMOID_INC",IF(C38="Сигмоида (убывание)","SIGMOID_DEC",IF(C38="ТОП %","TOP_PERCENT",IF(C38="Ручное μ","MANUAL_MU",IF(C38="Количество + флаг","COUNT_FLAG_RULE",IF(C38="Все условия «Да»","AND_YES",IF(C38="Любое условие «Да»","OR_YES","")))))))))))))))) | R38: 1e-09 | S38: 1 | T38: =IF(L38="Минимум","LOW_MU",IF(L38="Не учитывать","IGNORE","BLOCK")) -> BLOCK
A39: Нет | D39: 0 | I39: 1 | J39: 0.1 | K39: Нет | L39: Блокировать | M39: Свободный критерий | O39: 19 | P39: =IF(C39="Да / Нет","YES_NO",IF(C39="Не меньше порога","THRESHOLD_GE",IF(C39="Больше порога","THRESHOLD_GT",IF(C39="Не больше порога","THRESHOLD_LE",IF(C39="Меньше порога","THRESHOLD_LT",IF(C39="Рост показателя","CHANGE_PCT_GE",IF(C39="Изменение показателя","CHANGE_ABS_GE",IF(C39="Количество меньше","COUNT_LT",IF(C39="Количество не больше","COUNT_LE",IF(C39="Сигмоида","SIGMOID_INC",IF(C39="Сигмоида (убывание)","SIGMOID_DEC",IF(C39="ТОП %","TOP_PERCENT",IF(C39="Ручное μ","MANUAL_MU",IF(C39="Количество + флаг","COUNT_FLAG_RULE",IF(C39="Все условия «Да»","AND_YES",IF(C39="Любое условие «Да»","OR_YES","")))))))))))))))) | R39: 1e-09 | S39: 1 | T39: =IF(L39="Минимум","LOW_MU",IF(L39="Не учитывать","IGNORE","BLOCK")) -> BLOCK
A40: Нет | D40: 0 | I40: 1 | J40: 0.1 | K40: Нет | L40: Блокировать | M40: Свободный критерий | O40: 20 | P40: =IF(C40="Да / Нет","YES_NO",IF(C40="Не меньше порога","THRESHOLD_GE",IF(C40="Больше порога","THRESHOLD_GT",IF(C40="Не больше порога","THRESHOLD_LE",IF(C40="Меньше порога","THRESHOLD_LT",IF(C40="Рост показателя","CHANGE_PCT_GE",IF(C40="Изменение показателя","CHANGE_ABS_GE",IF(C40="Количество меньше","COUNT_LT",IF(C40="Количество не больше","COUNT_LE",IF(C40="Сигмоида","SIGMOID_INC",IF(C40="Сигмоида (убывание)","SIGMOID_DEC",IF(C40="ТОП %","TOP_PERCENT",IF(C40="Ручное μ","MANUAL_MU",IF(C40="Количество + флаг","COUNT_FLAG_RULE",IF(C40="Все условия «Да»","AND_YES",IF(C40="Любое условие «Да»","OR_YES","")))))))))))))))) | R40: 1e-09 | S40: 1 | T40: =IF(L40="Минимум","LOW_MU",IF(L40="Не учитывать","IGNORE","BLOCK")) -> BLOCK
A41: Нет | D41: 0 | I41: 1 | J41: 0.1 | K41: Нет | L41: Блокировать | M41: Свободный критерий | O41: 21 | P41: =IF(C41="Да / Нет","YES_NO",IF(C41="Не меньше порога","THRESHOLD_GE",IF(C41="Больше порога","THRESHOLD_GT",IF(C41="Не больше порога","THRESHOLD_LE",IF(C41="Меньше порога","THRESHOLD_LT",IF(C41="Рост показателя","CHANGE_PCT_GE",IF(C41="Изменение показателя","CHANGE_ABS_GE",IF(C41="Количество меньше","COUNT_LT",IF(C41="Количество не больше","COUNT_LE",IF(C41="Сигмоида","SIGMOID_INC",IF(C41="Сигмоида (убывание)","SIGMOID_DEC",IF(C41="ТОП %","TOP_PERCENT",IF(C41="Ручное μ","MANUAL_MU",IF(C41="Количество + флаг","COUNT_FLAG_RULE",IF(C41="Все условия «Да»","AND_YES",IF(C41="Любое условие «Да»","OR_YES","")))))))))))))))) | R41: 1e-09 | S41: 1 | T41: =IF(L41="Минимум","LOW_MU",IF(L41="Не учитывать","IGNORE","BLOCK")) -> BLOCK
...

Sheet Данные
A1: Данные — пример заполнения | B1: Данные — пример заполнения | C1: Данные — пример заполнения | D1: Данные — пример заполнения | E1: Данные — пример заполнения | F1: Данные — пример заполнения | G1: Данные — пример заполнения | H1: Данные — пример заполнения | I1: Данные — пример заполнения | J1: Данные — пример заполнения | K1: Данные — пример заполнения | L1: Данные — пример заполнения | M1: Данные — пример заполнения | N1: Данные — пример заполнения | O1: Данные — пример заполнения | P1: Данные — пример заполнения | Q1: Данные — пример заполнения | R1: Данные — пример заполнения | S1: Данные — пример заполнения | T1: Данные — пример заполнения | U1: Данные — пример заполнения | V1: Данные — пример заполнения | W1: Данные — пример заполнения | X1: Данные — пример заполнения | Y1: Данные — пример заполнения | Z1: Данные — пример заполнения
A2: Данные — пример заполнения | B2: Данные — пример заполнения | C2: Данные — пример заполнения | D2: Данные — пример заполнения | E2: Данные — пример заполнения | F2: Данные — пример заполнения | G2: Данные — пример заполнения | H2: Данные — пример заполнения | I2: Данные — пример заполнения | J2: Данные — пример заполнения | K2: Данные — пример заполнения | L2: Данные — пример заполнения | M2: Данные — пример заполнения | N2: Данные — пример заполнения | O2: Данные — пример заполнения | P2: Данные — пример заполнения | Q2: Данные — пример заполнения | R2: Данные — пример заполнения | S2: Данные — пример заполнения | T2: Данные — пример заполнения | U2: Данные — пример заполнения | V2: Данные — пример заполнения | W2: Данные — пример заполнения | X2: Данные — пример заполнения | Y2: Данные — пример заполнения | Z2: Данные — пример заполнения
A4: Желтые ячейки — ввод данных. Одна строка соответствует одной скважине. | B4: Желтые ячейки — ввод пользователя. Заголовки являются стабильным интерфейсом: критерии находят поля по имени, а не по номеру колонки. | C4: Желтые ячейки — ввод пользователя. Заголовки являются стабильным интерфейсом: критерии находят поля по имени, а не по номеру колонки. | D4: Желтые ячейки — ввод пользователя. Заголовки являются стабильным интерфейсом: критерии находят поля по имени, а не по номеру колонки. | E4: Желтые ячейки — ввод пользователя. Заголовки являются стабильным интерфейсом: критерии находят поля по имени, а не по номеру колонки. | F4: Желтые ячейки — ввод пользователя. Заголовки являются стабильным интерфейсом: критерии находят поля по имени, а не по номеру колонки. | G4: Желтые ячейки — ввод пользователя. Заголовки являются стабильным интерфейсом: критерии находят поля по имени, а не по номеру колонки. | H4: Желтые ячейки — ввод пользователя. Заголовки являются стабильным интерфейсом: критерии находят поля по имени, а не по номеру колонки. | I4: Желтые ячейки — ввод пользователя. Заголовки являются стабильным интерфейсом: критерии находят поля по имени, а не по номеру колонки. | J4: Желтые ячейки — ввод пользователя. Заголовки являются стабильным интерфейсом: критерии находят поля по имени, а не по номеру колонки. | K4: Желтые ячейки — ввод пользователя. Заголовки являются стабильным интерфейсом: критерии находят поля по имени, а не по номеру колонки. | L4: Желтые ячейки — ввод пользователя. Заголовки являются стабильным интерфейсом: критерии находят поля по имени, а не по номеру колонки. | M4: Желтые ячейки — ввод пользователя. Заголовки являются стабильным интерфейсом: критерии находят поля по имени, а не по номеру колонки. | N4: Желтые ячейки — ввод пользователя. Заголовки являются стабильным интерфейсом: критерии находят поля по имени, а не по номеру колонки. | O4: Желтые ячейки — ввод пользователя. Заголовки являются стабильным интерфейсом: критерии находят поля по имени, а не по номеру колонки. | P4: Желтые ячейки — ввод пользователя. Заголовки являются стабильным интерфейсом: критерии находят поля по имени, а не по номеру колонки. | Q4: Желтые ячейки — ввод пользователя. Заголовки являются стабильным интерфейсом: критерии находят поля по имени, а не по номеру колонки. | R4: Желтые ячейки — ввод пользователя. Заголовки являются стабильным интерфейсом: критерии находят поля по имени, а не по номеру колонки. | S4: Желтые ячейки — ввод пользователя. Заголовки являются стабильным интерфейсом: критерии находят поля по имени, а не по номеру колонки. | T4: Желтые ячейки — ввод пользователя. Заголовки являются стабильным интерфейсом: критерии находят поля по имени, а не по номеру колонки. | U4: Желтые ячейки — ввод пользователя. Заголовки являются стабильным интерфейсом: критерии находят поля по имени, а не по номеру колонки. | V4: Желтые ячейки — ввод пользователя. Заголовки являются стабильным интерфейсом: критерии находят поля по имени, а не по номеру колонки. | W4: Желтые ячейки — ввод пользователя. Заголовки являются стабильным интерфейсом: критерии находят поля по имени, а не по номеру колонки. | X4: Желтые ячейки — ввод пользователя. Заголовки являются стабильным интерфейсом: критерии находят поля по имени, а не по номеру колонки. | Y4: Желтые ячейки — ввод пользователя. Заголовки являются стабильным интерфейсом: критерии находят поля по имени, а не по номеру колонки. | Z4: Желтые ячейки — ввод пользователя. Заголовки являются стабильным интерфейсом: критерии находят поля по имени, а не по номеру колонки.
A6: Скважина | B6: Пласт | C6: Состояние | D6: Дата запуска | E6: Количество ГДИ | F6: Глубинные датчики | G6: Расходомер | H6: ГТМ | I6: Недостаточно ГДИС | J6: Снижение продуктивности | K6: Рост хлора | L6: Cl текущий | M6: Cl предыдущий | N6: Проблемы ГДМ | O6: ЛНД | P6: Последний АДД | Q6: Не проведен АДД | R6: Продолжительность без ГДИ | S6: Удельное количество ГДИ | T6: ВГФ текущий | U6: ВГФ предыдущий | V6: Продолжительность без ИД | W6: Продолжительность без КВД | X6: Техническая возможность | Y6: Дебит | Z6: Manual μ
A7: 11_ЗБС | B7: ПК1 | C7: В работе | D7: 44052 | E7: 5 | H7: Нет | I7: Нет | J7: Нет | K7: Нет | N7: Нет | O7: Нет | Q7: Да | R7: 1.3260274 | S7: 0.9709589 | X7: Да
A8: 051_ЗБС | B8: ПК1 | C8: В работе | D8: 43971 | E8: 9 | H8: Нет | I8: Нет | J8: Нет | K8: Нет | N8: Нет | O8: Да | Q8: Да | R8: 0.44383562 | S8: 0.56407915 | X8: Да
A9: 072_ЗБС | B9: ПК1 | C9: В работе | D9: 42227 | E9: 9 | H9: Нет | I9: Нет | J9: Нет | K9: Да | N9: Да | O9: Да | Q9: Да | R9: 1.7287671 | S9: 1.0949772 | X9: Да
A10: 081 | B10: ПК1 | C10: В работе | D10: 39234 | E10: 16 | H10: Нет | I10: Нет | J10: Нет | K10: Да | N10: Нет | O10: Нет | Q10: Да | R10: 1.2630137 | S10: 1.1284247 | X10: Да
A11: 222_ЗБС2 | B11: ПК1 | C11: В работе | D11: 45506 | E11: 1 | H11: Нет | I11: Нет | J11: Нет | K11: Да | N11: Нет | O11: Да | Q11: Да | R11: 0.8739726 | S11: 0.87123288 | X11: Да
A12: 10601_ЗБС | B12: ПК-19-1-2 | C12: В работе | D12: 43313 | E12: 11 | H12: Нет | I12: Нет | J12: Да | K12: Нет | N12: Нет | O12: Нет | Q12: Нет | R12: 0.1890411 | S12: 0.62540473 | X12: Да
A13: 10502_ЗБС | B13: АТ-8-1-1 | C13: В бездействии | D13: 45202 | E13: 7 | H13: Да | I13: Нет | J13: Нет | K13: Да | N13: Нет | O13: Да | Q13: Да | R13: 0.44109589 | S13: 0.24344423 | X13: Да
A14: 10901_КЛК | B14: ПК19-20 | C14: В работе | D14: 45768 | E14: 0 | H14: Да | I14: Да | J14: Нет | K14: Да | N14: Нет | O14: Нет | Q14: Нет | R14: 0.15342466 | S14: 0.15342466 | X14: Да
A15: 11001 | B15: ПК19-20 | C15: Ожидает запуск | D15: 44835 | E15: 1 | H15: Нет | I15: Да | J15: Нет | K15: Нет | N15: Нет | O15: Да | Q15: Да | R15: 2.6 | S15: 2.709589 | X15: Да
A16: 054_ПВЛГ | B16: ПК14 | C16: В работе | D16: 45717 | E16: 2 | H16: Нет | I16: Нет | J16: Нет | K16: Да | N16: Нет | O16: Нет | Q16: Да | R16: 0.11506849 | S16: 0.14657534 | X16: Да
A17: 10802 | B17: ПК-19-2+20 | C17: В работе | D17: 43374 | E17: 8 | H17: Нет | I17: Нет | J17: Да | K17: Да | N17: Да | O17: Нет | Q17: Да | R17: 0.35890411 | S17: 0.8390411 | X17: Да
A18: 10305_ЗБС | B18: ПК-19-2 | C18: В работе | D18: 44713 | E18: 10 | H18: Нет | I18: Нет | J18: Да | K18: Да | N18: Да | O18: Нет | Q18: Нет | R18: 0.76986301 | S18: 0.30438356 | X18: Да
A19: 322 | B19: ПК-1 | C19: В работе | D19: 43619 | E19: 13 | H19: Нет | I19: Нет | J19: Да | K19: Нет | N19: Да | O19: Нет | Q19: Да | R19: 0.81369863 | S19: 0.46469968 | X19: Да

Sheet Критерии
A1: Критерии — значения μ по скважинам | B1: Критерии — исходное значение → μ → вес | C1: Критерии — исходное значение → μ → вес | D1: Критерии — исходное значение → μ → вес | E1: Критерии — исходное значение → μ → вес | F1: Критерии — исходное значение → μ → вес | G1: Критерии — исходное значение → μ → вес | H1: Критерии — исходное значение → μ → вес | I1: Критерии — исходное значение → μ → вес | J1: Критерии — исходное значение → μ → вес | K1: Критерии — исходное значение → μ → вес | L1: Критерии — исходное значение → μ → вес | M1: Критерии — исходное значение → μ → вес | N1: Критерии — исходное значение → μ → вес | O1: Критерии — исходное значение → μ → вес | P1: Критерии — исходное значение → μ → вес | Q1: Критерии — исходное значение → μ → вес | R1: Критерии — исходное значение → μ → вес | S1: Критерии — исходное значение → μ → вес | T1: Критерии — исходное значение → μ → вес | U1: Критерии — исходное значение → μ → вес | V1: Критерии — исходное значение → μ → вес | W1: Критерии — исходное значение → μ → вес | X1: Критерии — исходное значение → μ → вес | Y1: Критерии — исходное значение → μ → вес | Z1: Критерии — исходное значение → μ → вес | AA1: Критерии — исходное значение → μ → вес | AB1: Критерии — исходное значение → μ → вес | AC1: Критерии — исходное значение → μ → вес | AD1: Критерии — исходное значение → μ → вес | AE1: Критерии — исходное значение → μ → вес | AF1: Критерии — исходное значение → μ → вес | AG1: Критерии — исходное значение → μ → вес | AH1: Критерии — исходное значение → μ → вес | AI1: Критерии — исходное значение → μ → вес | AJ1: Критерии — исходное значение → μ → вес | AK1: Критерии — исходное значение → μ → вес | AL1: Критерии — исходное значение → μ → вес | AM1: Критерии — исходное значение → μ → вес | AN1: Критерии — исходное значение → μ → вес | AO1: Критерии — исходное значение → μ → вес | AP1: Критерии — исходное значение → μ → вес | AQ1: Критерии — исходное значение → μ → вес | AR1: Критерии — исходное значение → μ → вес | AS1: Критерии — исходное значение → μ → вес | AT1: Критерии — исходное значение → μ → вес | AU1: Критерии — исходное значение → μ → вес | AV1: Критерии — исходное значение → μ → вес | AW1: Критерии — исходное значение → μ → вес | AX1: Критерии — исходное значение → μ → вес | AY1: Критерии — исходное значение → μ → вес | AZ1: Критерии — исходное значение → μ → вес | BA1: Критерии — исходное значение → μ → вес | BB1: Критерии — исходное значение → μ → вес | BC1: Критерии — исходное значение → μ → вес | BD1: Критерии — исходное значение → μ → вес | BE1: Критерии — исходное значение → μ → вес | BF1: Критерии — исходное значение → μ → вес | BG1: Критерии — исходное значение → μ → вес | BH1: Критерии — исходное значение → μ → вес | BI1: Критерии — исходное значение → μ → вес | BJ1: Критерии — исходное значение → μ → вес | BK1: Критерии — исходное значение → μ → вес | BL1: Критерии — исходное значение → μ → вес | BM1: Критерии — исходное значение → μ → вес | BN1: Критерии — исходное значение → μ → вес | BO1: Критерии — исходное значение → μ → вес | BP1: Критерии — исходное значение → μ → вес | BQ1: Критерии — исходное значение → μ → вес | BR1: Критерии — исходное значение → μ → вес | BS1: Критерии — исходное значение → μ → вес | BT1: Критерии — исходное значение → μ → вес | BU1: Критерии — исходное значение → μ → вес | BV1: Критерии — исходное значение → μ → вес | BW1: Критерии — исходное значение → μ → вес | BX1: Критерии — исходное значение → μ → вес | BY1: Критерии — исходное значение → μ → вес | BZ1: Критерии — исходное значение → μ → вес | CA1: Критерии — исходное значение → μ → вес | CB1: Критерии — исходное значение → μ → вес | CC1: Критерии — исходное значение → μ → вес | CD1: Критерии — исходное значение → μ → вес | CE1: Критерии — исходное значение → μ → вес | CF1: Критерии — исходное значение → μ → вес | CG1: Критерии — исходное значение → μ → вес | CH1: Критерии — исходное значение → μ → вес | CI1: Критерии — исходное значение → μ → вес | CJ1: Критерии — исходное значение → μ → вес | CK1: Критерии — исходное значение → μ → вес | CL1: Критерии — исходное значение → μ → вес | CM1: Критерии — исходное значение → μ → вес | CN1: Критерии — исходное значение → μ → вес | CO1: Критерии — исходное значение → μ → вес
A2: Скважина | B2: μ по критериям | C2: μ ПО КРИТЕРИЯМ | D2: μ ПО КРИТЕРИЯМ | E2: μ ПО КРИТЕРИЯМ | F2: μ ПО КРИТЕРИЯМ | G2: μ ПО КРИТЕРИЯМ | H2: μ ПО КРИТЕРИЯМ | I2: μ ПО КРИТЕРИЯМ | J2: μ ПО КРИТЕРИЯМ | K2: μ ПО КРИТЕРИЯМ | L2: μ ПО КРИТЕРИЯМ | M2: μ ПО КРИТЕРИЯМ | N2: μ ПО КРИТЕРИЯМ | O2: μ ПО КРИТЕРИЯМ | P2: μ ПО КРИТЕРИЯМ | Q2: μ ПО КРИТЕРИЯМ | R2: μ ПО КРИТЕРИЯМ | S2: μ ПО КРИТЕРИЯМ | T2: μ ПО КРИТЕРИЯМ | U2: μ ПО КРИТЕРИЯМ | V2: μ ПО КРИТЕРИЯМ | W2: μ ПО КРИТЕРИЯМ | X2: μ ПО КРИТЕРИЯМ | Y2: μ ПО КРИТЕРИЯМ | Z2: μ ПО КРИТЕРИЯМ | AA2: μ ПО КРИТЕРИЯМ | AB2: μ ПО КРИТЕРИЯМ | AC2: μ ПО КРИТЕРИЯМ | AD2: μ ПО КРИТЕРИЯМ | AE2: μ ПО КРИТЕРИЯМ | AG2: ИСХОДНОЕ ЗНАЧЕНИЕ 1 | AH2: ИСХОДНОЕ ЗНАЧЕНИЕ 1 | AI2: ИСХОДНОЕ ЗНАЧЕНИЕ 1 | AJ2: ИСХОДНОЕ ЗНАЧЕНИЕ 1 | AK2: ИСХОДНОЕ ЗНАЧЕНИЕ 1 | AL2: ИСХОДНОЕ ЗНАЧЕНИЕ 1 | AM2: ИСХОДНОЕ ЗНАЧЕНИЕ 1 | AN2: ИСХОДНОЕ ЗНАЧЕНИЕ 1 | AO2: ИСХОДНОЕ ЗНАЧЕНИЕ 1 | AP2: ИСХОДНОЕ ЗНАЧЕНИЕ 1 | AQ2: ИСХОДНОЕ ЗНАЧЕНИЕ 1 | AR2: ИСХОДНОЕ ЗНАЧЕНИЕ 1 | AS2: ИСХОДНОЕ ЗНАЧЕНИЕ 1 | AT2: ИСХОДНОЕ ЗНАЧЕНИЕ 1 | AU2: ИСХОДНОЕ ЗНАЧЕНИЕ 1 | AV2: ИСХОДНОЕ ЗНАЧЕНИЕ 1 | AW2: ИСХОДНОЕ ЗНАЧЕНИЕ 1 | AX2: ИСХОДНОЕ ЗНАЧЕНИЕ 1 | AY2: ИСХОДНОЕ ЗНАЧЕНИЕ 1 | AZ2: ИСХОДНОЕ ЗНАЧЕНИЕ 1 | BA2: ИСХОДНОЕ ЗНАЧЕНИЕ 1 | BB2: ИСХОДНОЕ ЗНАЧЕНИЕ 1 | BC2: ИСХОДНОЕ ЗНАЧЕНИЕ 1 | BD2: ИСХОДНОЕ ЗНАЧЕНИЕ 1 | BE2: ИСХОДНОЕ ЗНАЧЕНИЕ 1 | BF2: ИСХОДНОЕ ЗНАЧЕНИЕ 1 | BG2: ИСХОДНОЕ ЗНАЧЕНИЕ 1 | BH2: ИСХОДНОЕ ЗНАЧЕНИЕ 1 | BI2: ИСХОДНОЕ ЗНАЧЕНИЕ 1 | BJ2: ИСХОДНОЕ ЗНАЧЕНИЕ 1 | BL2: ИСХОДНОЕ ЗНАЧЕНИЕ 2 | BM2: ИСХОДНОЕ ЗНАЧЕНИЕ 2 | BN2: ИСХОДНОЕ ЗНАЧЕНИЕ 2 | BO2: ИСХОДНОЕ ЗНАЧЕНИЕ 2 | BP2: ИСХОДНОЕ ЗНАЧЕНИЕ 2 | BQ2: ИСХОДНОЕ ЗНАЧЕНИЕ 2 | BR2: ИСХОДНОЕ ЗНАЧЕНИЕ 2 | BS2: ИСХОДНОЕ ЗНАЧЕНИЕ 2 | BT2: ИСХОДНОЕ ЗНАЧЕНИЕ 2 | BU2: ИСХОДНОЕ ЗНАЧЕНИЕ 2 | BV2: ИСХОДНОЕ ЗНАЧЕНИЕ 2 | BW2: ИСХОДНОЕ ЗНАЧЕНИЕ 2 | BX2: ИСХОДНОЕ ЗНАЧЕНИЕ 2 | BY2: ИСХОДНОЕ ЗНАЧЕНИЕ 2 | BZ2: ИСХОДНОЕ ЗНАЧЕНИЕ 2 | CA2: ИСХОДНОЕ ЗНАЧЕНИЕ 2 | CB2: ИСХОДНОЕ ЗНАЧЕНИЕ 2 | CC2: ИСХОДНОЕ ЗНАЧЕНИЕ 2 | CD2: ИСХОДНОЕ ЗНАЧЕНИЕ 2 | CE2: ИСХОДНОЕ ЗНАЧЕНИЕ 2 | CF2: ИСХОДНОЕ ЗНАЧЕНИЕ 2 | CG2: ИСХОДНОЕ ЗНАЧЕНИЕ 2 | CH2: ИСХОДНОЕ ЗНАЧЕНИЕ 2 | CI2: ИСХОДНОЕ ЗНАЧЕНИЕ 2 | CJ2: ИСХОДНОЕ ЗНАЧЕНИЕ 2 | CK2: ИСХОДНОЕ ЗНАЧЕНИЕ 2 | CL2: ИСХОДНОЕ ЗНАЧЕНИЕ 2 | CM2: ИСХОДНОЕ ЗНАЧЕНИЕ 2 | CN2: ИСХОДНОЕ ЗНАЧЕНИЕ 2 | CO2: ИСХОДНОЕ ЗНАЧЕНИЕ 2
A3: Код | B3: =Настройки!$N$21 -> C01_GTM | C3: =Настройки!$N$22 -> C02_GDIS | D3: =Настройки!$N$23 -> C03_PROD | E3: =Настройки!$N$24 -> C04_CL | F3: =Настройки!$N$25 -> C05_GDM | G3: =Настройки!$N$26 -> C06_LND | H3: =Настройки!$N$27 -> C07_NO_GDI | I3: =Настройки!$N$28 -> C08_NO_ADD | J3: =Настройки!$N$29 -> C09_SPEC_GDI | K3: =Настройки!$N$30 -> C10_VGF_GROWTH | L3: =Настройки!$N$31 -> C11_VGF_LIMIT | M3: =Настройки!$N$32 -> C12_NO_ID | N3: =Настройки!$N$33 -> C13_NO_KVD | O3: =Настройки!$N$34 -> C14_TECH | P3: =Настройки!$N$35 -> C15_TOP_DEBIT | Q3: =Настройки!$N$36 -> C16_GDIS_RULE | R3: =Настройки!$N$37 -> 0 | S3: =Настройки!$N$38 -> 0 | T3: =Настройки!$N$39 -> 0 | U3: =Настройки!$N$40 -> 0 | V3: =Настройки!$N$41 -> 0 | W3: =Настройки!$N$42 -> 0 | X3: =Настройки!$N$43 -> 0 | Y3: =Настройки!$N$44 -> 0 | Z3: =Настройки!$N$45 -> 0 | AA3: =Настройки!$N$46 -> 0 | AB3: =Настройки!$N$47 -> 0 | AC3: =Настройки!$N$48 -> 0 | AD3: =Настройки!$N$49 -> 0 | AE3: =Настройки!$N$50 -> 0 | AG3: =Настройки!$N$21 -> C01_GTM | AH3: =Настройки!$N$22 -> C02_GDIS | AI3: =Настройки!$N$23 -> C03_PROD | AJ3: =Настройки!$N$24 -> C04_CL | AK3: =Настройки!$N$25 -> C05_GDM | AL3: =Настройки!$N$26 -> C06_LND | AM3: =Настройки!$N$27 -> C07_NO_GDI | AN3: =Настройки!$N$28 -> C08_NO_ADD | AO3: =Настройки!$N$29 -> C09_SPEC_GDI | AP3: =Настройки!$N$30 -> C10_VGF_GROWTH | AQ3: =Настройки!$N$31 -> C11_VGF_LIMIT | AR3: =Настройки!$N$32 -> C12_NO_ID | AS3: =Настройки!$N$33 -> C13_NO_KVD | AT3: =Настройки!$N$34 -> C14_TECH | AU3: =Настройки!$N$35 -> C15_TOP_DEBIT | AV3: =Настройки!$N$36 -> C16_GDIS_RULE | AW3: =Настройки!$N$37 -> 0 | AX3: =Настройки!$N$38 -> 0 | AY3: =Настройки!$N$39 -> 0 | AZ3: =Настройки!$N$40 -> 0 | BA3: =Настройки!$N$41 -> 0 | BB3: =Настройки!$N$42 -> 0 | BC3: =Настройки!$N$43 -> 0 | BD3: =Настройки!$N$44 -> 0 | BE3: =Настройки!$N$45 -> 0 | BF3: =Настройки!$N$46 -> 0 | BG3: =Настройки!$N$47 -> 0 | BH3: =Настройки!$N$48 -> 0 | BI3: =Настройки!$N$49 -> 0 | BJ3: =Настройки!$N$50 -> 0 | BL3: =Настройки!$N$21 -> C01_GTM | BM3: =Настройки!$N$22 -> C02_GDIS | BN3: =Настройки!$N$23 -> C03_PROD | BO3: =Настройки!$N$24 -> C04_CL | BP3: =Настройки!$N$25 -> C05_GDM | BQ3: =Настройки!$N$26 -> C06_LND | BR3: =Настройки!$N$27 -> C07_NO_GDI | BS3: =Настройки!$N$28 -> C08_NO_ADD | BT3: =Настройки!$N$29 -> C09_SPEC_GDI | BU3: =Настройки!$N$30 -> C10_VGF_GROWTH | BV3: =Настройки!$N$31 -> C11_VGF_LIMIT | BW3: =Настройки!$N$32 -> C12_NO_ID | BX3: =Настройки!$N$33 -> C13_NO_KVD | BY3: =Настройки!$N$34 -> C14_TECH | BZ3: =Настройки!$N$35 -> C15_TOP_DEBIT | CA3: =Настройки!$N$36 -> C16_GDIS_RULE | CB3: =Настройки!$N$37 -> 0 | CC3: =Настройки!$N$38 -> 0 | CD3: =Настройки!$N$39 -> 0 | CE3: =Настройки!$N$40 -> 0 | CF3: =Настройки!$N$41 -> 0 | CG3: =Настройки!$N$42 -> 0 | CH3: =Настройки!$N$43 -> 0 | CI3: =Настройки!$N$44 -> 0 | CJ3: =Настройки!$N$45 -> 0 | CK3: =Настройки!$N$46 -> 0 | CL3: =Настройки!$N$47 -> 0 | CM3: =Настройки!$N$48 -> 0 | CN3: =Настройки!$N$49 -> 0 | CO3: =Настройки!$N$50 -> 0
A4: Использовать | B4: =Настройки!$A$21 -> Да | C4: =Настройки!$A$22 -> Да | D4: =Настройки!$A$23 -> Да | E4: =Настройки!$A$24 -> Да | F4: =Настройки!$A$25 -> Да | G4: =Настройки!$A$26 -> Да | H4: =Настройки!$A$27 -> Да | I4: =Настройки!$A$28 -> Да | J4: =Настройки!$A$29 -> Да | K4: =Настройки!$A$30 -> Нет | L4: =Настройки!$A$31 -> Нет | M4: =Настройки!$A$32 -> Нет | N4: =Настройки!$A$33 -> Нет | O4: =Настройки!$A$34 -> Нет | P4: =Настройки!$A$35 -> Нет | Q4: =Настройки!$A$36 -> Нет | R4: =Настройки!$A$37 -> Нет | S4: =Настройки!$A$38 -> Нет | T4: =Настройки!$A$39 -> Нет | U4: =Настройки!$A$40 -> Нет | V4: =Настройки!$A$41 -> Нет | W4: =Настройки!$A$42 -> Нет | X4: =Настройки!$A$43 -> Нет | Y4: =Настройки!$A$44 -> Нет | Z4: =Настройки!$A$45 -> Нет | AA4: =Настройки!$A$46 -> Нет | AB4: =Настройки!$A$47 -> Нет | AC4: =Настройки!$A$48 -> Нет | AD4: =Настройки!$A$49 -> Нет | AE4: =Настройки!$A$50 -> Нет | AG4: =Настройки!$A$21 -> Да | AH4: =Настройки!$A$22 -> Да | AI4: =Настройки!$A$23 -> Да | AJ4: =Настройки!$A$24 -> Да | AK4: =Настройки!$A$25 -> Да | AL4: =Настройки!$A$26 -> Да | AM4: =Настройки!$A$27 -> Да | AN4: =Настройки!$A$28 -> Да | AO4: =Настройки!$A$29 -> Да | AP4: =Настройки!$A$30 -> Нет | AQ4: =Настройки!$A$31 -> Нет | AR4: =Настройки!$A$32 -> Нет | AS4: =Настройки!$A$33 -> Нет | AT4: =Настройки!$A$34 -> Нет | AU4: =Настройки!$A$35 -> Нет | AV4: =Настройки!$A$36 -> Нет | AW4: =Настройки!$A$37 -> Нет | AX4: =Настройки!$A$38 -> Нет | AY4: =Настройки!$A$39 -> Нет | AZ4: =Настройки!$A$40 -> Нет | BA4: =Настройки!$A$41 -> Нет | BB4: =Настройки!$A$42 -> Нет | BC4: =Настройки!$A$43 -> Нет | BD4: =Настройки!$A$44 -> Нет | BE4: =Настройки!$A$45 -> Нет | BF4: =Настройки!$A$46 -> Нет | BG4: =Настройки!$A$47 -> Нет | BH4: =Настройки!$A$48 -> Нет | BI4: =Настройки!$A$49 -> Нет | BJ4: =Настройки!$A$50 -> Нет | BL4: =Настройки!$A$21 -> Да | BM4: =Настройки!$A$22 -> Да | BN4: =Настройки!$A$23 -> Да | BO4: =Настройки!$A$24 -> Да | BP4: =Настройки!$A$25 -> Да | BQ4: =Настройки!$A$26 -> Да | BR4: =Настройки!$A$27 -> Да | BS4: =Настройки!$A$28 -> Да | BT4: =Настройки!$A$29 -> Да | BU4: =Настройки!$A$30 -> Нет | BV4: =Настройки!$A$31 -> Нет | BW4: =Настройки!$A$32 -> Нет | BX4: =Настройки!$A$33 -> Нет | BY4: =Настройки!$A$34 -> Нет | BZ4: =Настройки!$A$35 -> Нет | CA4: =Настройки!$A$36 -> Нет | CB4: =Настройки!$A$37 -> Нет | CC4: =Настройки!$A$38 -> Нет | CD4: =Настройки!$A$39 -> Нет | CE4: =Настройки!$A$40 -> Нет | CF4: =Настройки!$A$41 -> Нет | CG4: =Настройки!$A$42 -> Нет | CH4: =Настройки!$A$43 -> Нет | CI4: =Настройки!$A$44 -> Нет | CJ4: =Настройки!$A$45 -> Нет | CK4: =Настройки!$A$46 -> Нет | CL4: =Настройки!$A$47 -> Нет | CM4: =Настройки!$A$48 -> Нет | CN4: =Настройки!$A$49 -> Нет | CO4: =Настройки!$A$50 -> Нет
A5: Критерий | B5: =Настройки!$B$21 -> Запланировано или проведено ГТМ | C5: =Настройки!$B$22 -> Недостаточно ГДИС для создания модели пласт-скважина | D5: =Настройки!$B$23 -> Наблюдается снижение продуктивности | E5: =Настройки!$B$24 -> Рост хлора | F5: =Настройки!$B$25 -> Проблемы с адаптацией в ГДМ | G5: =Настройки!$B$26 -> Невыход на радиальный режим / низкая достоверность ЛНД | H5: =Настройки!$B$27 -> Продолжительность пребывания без ГДИ | I5: =Настройки!$B$28 -> Не проведен АДД за скользящий год | J5: =Настройки!$B$29 -> Удельное количество ГДИ от накопленного периода работы | K5: =Настройки!$B$30 -> Рост ВГФ | L5: =Настройки!$B$31 -> Превышение предельного ВГФ | M5: =Настройки!$B$32 -> Продолжительность пребывания без ИД | N5: =Настройки!$B$33 -> Продолжительность пребывания без КВД | O5: =Настройки!$B$34 -> Возможность проведения исследований | P5: =Настройки!$B$35 -> Высокодебитные скважины | Q5: =Настройки!$B$36 -> Достаточность ГДИС с учетом стационарного оснащения | R5: =Настройки!$B$37 -> 0 | S5: =Настройки!$B$38 -> 0 | T5: =Настройки!$B$39 -> 0 | U5: =Настройки!$B$40 -> 0 | V5: =Настройки!$B$41 -> 0 | W5: =Настройки!$B$42 -> 0 | X5: =Настройки!$B$43 -> 0 | Y5: =Настройки!$B$44 -> 0 | Z5: =Настройки!$B$45 -> 0 | AA5: =Настройки!$B$46 -> 0 | AB5: =Настройки!$B$47 -> 0 | AC5: =Настройки!$B$48 -> 0 | AD5: =Настройки!$B$49 -> 0 | AE5: =Настройки!$B$50 -> 0 | AG5: =Настройки!$B$21 -> Запланировано или проведено ГТМ | AH5: =Настройки!$B$22 -> Недостаточно ГДИС для создания модели пласт-скважина | AI5: =Настройки!$B$23 -> Наблюдается снижение продуктивности | AJ5: =Настройки!$B$24 -> Рост хлора | AK5: =Настройки!$B$25 -> Проблемы с адаптацией в ГДМ | AL5: =Настройки!$B$26 -> Невыход на радиальный режим / низкая достоверность ЛНД | AM5: =Настройки!$B$27 -> Продолжительность пребывания без ГДИ | AN5: =Настройки!$B$28 -> Не проведен АДД за скользящий год | AO5: =Настройки!$B$29 -> Удельное количество ГДИ от накопленного периода работы | AP5: =Настройки!$B$30 -> Рост ВГФ | AQ5: =Настройки!$B$31 -> Превышение предельного ВГФ | AR5: =Настройки!$B$32 -> Продолжительность пребывания без ИД | AS5: =Настройки!$B$33 -> Продолжительность пребывания без КВД | AT5: =Настройки!$B$34 -> Возможность проведения исследований | AU5: =Настройки!$B$35 -> Высокодебитные скважины | AV5: =Настройки!$B$36 -> Достаточность ГДИС с учетом стационарного оснащения | AW5: =Настройки!$B$37 -> 0 | AX5: =Настройки!$B$38 -> 0 | AY5: =Настройки!$B$39 -> 0 | AZ5: =Настройки!$B$40 -> 0 | BA5: =Настройки!$B$41 -> 0 | BB5: =Настройки!$B$42 -> 0 | BC5: =Настройки!$B$43 -> 0 | BD5: =Настройки!$B$44 -> 0 | BE5: =Настройки!$B$45 -> 0 | BF5: =Настройки!$B$46 -> 0 | BG5: =Настройки!$B$47 -> 0 | BH5: =Настройки!$B$48 -> 0 | BI5: =Настройки!$B$49 -> 0 | BJ5: =Настройки!$B$50 -> 0 | BL5: =Настройки!$B$21 -> Запланировано или проведено ГТМ | BM5: =Настройки!$B$22 -> Недостаточно ГДИС для создания модели пласт-скважина | BN5: =Настройки!$B$23 -> Наблюдается снижение продуктивности | BO5: =Настройки!$B$24 -> Рост хлора | BP5: =Настройки!$B$25 -> Проблемы с адаптацией в ГДМ | BQ5: =Настройки!$B$26 -> Невыход на радиальный режим / низкая достоверность ЛНД | BR5: =Настройки!$B$27 -> Продолжительность пребывания без ГДИ | BS5: =Настройки!$B$28 -> Не проведен АДД за скользящий год | BT5: =Настройки!$B$29 -> Удельное количество ГДИ от накопленного периода работы | BU5: =Настройки!$B$30 -> Рост ВГФ | BV5: =Настройки!$B$31 -> Превышение предельного ВГФ | BW5: =Настройки!$B$32 -> Продолжительность пребывания без ИД | BX5: =Настройки!$B$33 -> Продолжительность пребывания без КВД | BY5: =Настройки!$B$34 -> Возможность проведения исследований | BZ5: =Настройки!$B$35 -> Высокодебитные скважины | CA5: =Настройки!$B$36 -> Достаточность ГДИС с учетом стационарного оснащения | CB5: =Настройки!$B$37 -> 0 | CC5: =Настройки!$B$38 -> 0 | CD5: =Настройки!$B$39 -> 0 | CE5: =Настройки!$B$40 -> 0 | CF5: =Настройки!$B$41 -> 0 | CG5: =Настройки!$B$42 -> 0 | CH5: =Настройки!$B$43 -> 0 | CI5: =Настройки!$B$44 -> 0 | CJ5: =Настройки!$B$45 -> 0 | CK5: =Настройки!$B$46 -> 0 | CL5: =Настройки!$B$47 -> 0 | CM5: =Настройки!$B$48 -> 0 | CN5: =Настройки!$B$49 -> 0 | CO5: =Настройки!$B$50 -> 0
A6: Вес | B6: =Настройки!$D$21 -> 0.2 | C6: =Настройки!$D$22 -> 0.14 | D6: =Настройки!$D$23 -> 0.12 | E6: =Настройки!$D$24 -> 0.12 | F6: =Настройки!$D$25 -> 0.12 | G6: =Настройки!$D$26 -> 0.1 | H6: =Настройки!$D$27 -> 0.1 | I6: =Настройки!$D$28 -> 0.05 | J6: =Настройки!$D$29 -> 0.05 | K6: =Настройки!$D$30 -> 0.08 | L6: =Настройки!$D$31 -> 0.08 | M6: =Настройки!$D$32 -> 0.14 | N6: =Настройки!$D$33 -> 0.1 | O6: =Настройки!$D$34 -> 0.05 | P6: =Настройки!$D$35 -> 0.1 | Q6: =Настройки!$D$36 -> 0 | R6: =Настройки!$D$37 -> 0 | S6: =Настройки!$D$38 -> 0 | T6: =Настройки!$D$39 -> 0 | U6: =Настройки!$D$40 -> 0 | V6: =Настройки!$D$41 -> 0 | W6: =Настройки!$D$42 -> 0 | X6: =Настройки!$D$43 -> 0 | Y6: =Настройки!$D$44 -> 0 | Z6: =Настройки!$D$45 -> 0 | AA6: =Настройки!$D$46 -> 0 | AB6: =Настройки!$D$47 -> 0 | AC6: =Настройки!$D$48 -> 0 | AD6: =Настройки!$D$49 -> 0 | AE6: =Настройки!$D$50 -> 0 | AG6: =Настройки!$D$21 -> 0.2 | AH6: =Настройки!$D$22 -> 0.14 | AI6: =Настройки!$D$23 -> 0.12 | AJ6: =Настройки!$D$24 -> 0.12 | AK6: =Настройки!$D$25 -> 0.12 | AL6: =Настройки!$D$26 -> 0.1 | AM6: =Настройки!$D$27 -> 0.1 | AN6: =Настройки!$D$28 -> 0.05 | AO6: =Настройки!$D$29 -> 0.05 | AP6: =Настройки!$D$30 -> 0.08 | AQ6: =Настройки!$D$31 -> 0.08 | AR6: =Настройки!$D$32 -> 0.14 | AS6: =Настройки!$D$33 -> 0.1 | AT6: =Настройки!$D$34 -> 0.05 | AU6: =Настройки!$D$35 -> 0.1 | AV6: =Настройки!$D$36 -> 0 | AW6: =Настройки!$D$37 -> 0 | AX6: =Настройки!$D$38 -> 0 | AY6: =Настройки!$D$39 -> 0 | AZ6: =Настройки!$D$40 -> 0 | BA6: =Настройки!$D$41 -> 0 | BB6: =Настройки!$D$42 -> 0 | BC6: =Настройки!$D$43 -> 0 | BD6: =Настройки!$D$44 -> 0 | BE6: =Настройки!$D$45 -> 0 | BF6: =Настройки!$D$46 -> 0 | BG6: =Настройки!$D$47 -> 0 | BH6: =Настройки!$D$48 -> 0 | BI6: =Настройки!$D$49 -> 0 | BJ6: =Настройки!$D$50 -> 0 | BL6: =Настройки!$D$21 -> 0.2 | BM6: =Настройки!$D$22 -> 0.14 | BN6: =Настройки!$D$23 -> 0.12 | BO6: =Настройки!$D$24 -> 0.12 | BP6: =Настройки!$D$25 -> 0.12 | BQ6: =Настройки!$D$26 -> 0.1 | BR6: =Настройки!$D$27 -> 0.1 | BS6: =Настройки!$D$28 -> 0.05 | BT6: =Настройки!$D$29 -> 0.05 | BU6: =Настройки!$D$30 -> 0.08 | BV6: =Настройки!$D$31 -> 0.08 | BW6: =Настройки!$D$32 -> 0.14 | BX6: =Настройки!$D$33 -> 0.1 | BY6: =Настройки!$D$34 -> 0.05 | BZ6: =Настройки!$D$35 -> 0.1 | CA6: =Настройки!$D$36 -> 0 | CB6: =Настройки!$D$37 -> 0 | CC6: =Настройки!$D$38 -> 0 | CD6: =Настройки!$D$39 -> 0 | CE6: =Настройки!$D$40 -> 0 | CF6: =Настройки!$D$41 -> 0 | CG6: =Настройки!$D$42 -> 0 | CH6: =Настройки!$D$43 -> 0 | CI6: =Настройки!$D$44 -> 0 | CJ6: =Настройки!$D$45 -> 0 | CK6: =Настройки!$D$46 -> 0 | CL6: =Настройки!$D$47 -> 0 | CM6: =Настройки!$D$48 -> 0 | CN6: =Настройки!$D$49 -> 0 | CO6: =Настройки!$D$50 -> 0
A7: Основание | B7: =Настройки!$K$21 -> Да | C7: =Настройки!$K$22 -> Да | D7: =Настройки!$K$23 -> Да | E7: =Настройки!$K$24 -> Да | F7: =Настройки!$K$25 -> Да | G7: =Настройки!$K$26 -> Да | H7: =Настройки!$K$27 -> Нет | I7: =Настройки!$K$28 -> Да | J7: =Настройки!$K$29 -> Нет | K7: =Настройки!$K$30 -> Да | L7: =Настройки!$K$31 -> Да | M7: =Настройки!$K$32 -> Нет | N7: =Настройки!$K$33 -> Нет | O7: =Настройки!$K$34 -> Да | P7: =Настройки!$K$35 -> Нет | Q7: =Настройки!$K$36 -> Да | R7: =Настройки!$K$37 -> Нет | S7: =Настройки!$K$38 -> Нет | T7: =Настройки!$K$39 -> Нет | U7: =Настройки!$K$40 -> Нет | V7: =Настройки!$K$41 -> Нет | W7: =Настройки!$K$42 -> Нет | X7: =Настройки!$K$43 -> Нет | Y7: =Настройки!$K$44 -> Нет | Z7: =Настройки!$K$45 -> Нет | AA7: =Настройки!$K$46 -> Нет | AB7: =Настройки!$K$47 -> Нет | AC7: =Настройки!$K$48 -> Нет | AD7: =Настройки!$K$49 -> Нет | AE7: =Настройки!$K$50 -> Нет | AG7: =Настройки!$K$21 -> Да | AH7: =Настройки!$K$22 -> Да | AI7: =Настройки!$K$23 -> Да | AJ7: =Настройки!$K$24 -> Да | AK7: =Настройки!$K$25 -> Да | AL7: =Настройки!$K$26 -> Да | AM7: =Настройки!$K$27 -> Нет | AN7: =Настройки!$K$28 -> Да | AO7: =Настройки!$K$29 -> Нет | AP7: =Настройки!$K$30 -> Да | AQ7: =Настройки!$K$31 -> Да | AR7: =Настройки!$K$32 -> Нет | AS7: =Настройки!$K$33 -> Нет | AT7: =Настройки!$K$34 -> Да | AU7: =Настройки!$K$35 -> Нет | AV7: =Настройки!$K$36 -> Да | AW7: =Настройки!$K$37 -> Нет | AX7: =Настройки!$K$38 -> Нет | AY7: =Настройки!$K$39 -> Нет | AZ7: =Настройки!$K$40 -> Нет | BA7: =Настройки!$K$41 -> Нет | BB7: =Настройки!$K$42 -> Нет | BC7: =Настройки!$K$43 -> Нет | BD7: =Настройки!$K$44 -> Нет | BE7: =Настройки!$K$45 -> Нет | BF7: =Настройки!$K$46 -> Нет | BG7: =Настройки!$K$47 -> Нет | BH7: =Настройки!$K$48 -> Нет | BI7: =Настройки!$K$49 -> Нет | BJ7: =Настройки!$K$50 -> Нет | BL7: =Настройки!$K$21 -> Да | BM7: =Настройки!$K$22 -> Да | BN7: =Настройки!$K$23 -> Да | BO7: =Настройки!$K$24 -> Да | BP7: =Настройки!$K$25 -> Да | BQ7: =Настройки!$K$26 -> Да | BR7: =Настройки!$K$27 -> Нет | BS7: =Настройки!$K$28 -> Да | BT7: =Настройки!$K$29 -> Нет | BU7: =Настройки!$K$30 -> Да | BV7: =Настройки!$K$31 -> Да | BW7: =Настройки!$K$32 -> Нет | BX7: =Настройки!$K$33 -> Нет | BY7: =Настройки!$K$34 -> Да | BZ7: =Настройки!$K$35 -> Нет | CA7: =Настройки!$K$36 -> Да | CB7: =Настройки!$K$37 -> Нет | CC7: =Настройки!$K$38 -> Нет | CD7: =Настройки!$K$39 -> Нет | CE7: =Настройки!$K$40 -> Нет | CF7: =Настройки!$K$41 -> Нет | CG7: =Настройки!$K$42 -> Нет | CH7: =Настройки!$K$43 -> Нет | CI7: =Настройки!$K$44 -> Нет | CJ7: =Настройки!$K$45 -> Нет | CK7: =Настройки!$K$46 -> Нет | CL7: =Настройки!$K$47 -> Нет | CM7: =Настройки!$K$48 -> Нет | CN7: =Настройки!$K$49 -> Нет | CO7: =Настройки!$K$50 -> Нет
